Workbook

Sheet Bitacora
A1: PROYECCIÓN SCOTIABANK
A3: PARÁMETROS | E3: TARIFAS POR PRODUCTO
A4: UF | B4: =[1]Parámetros!B5 -> 40543.07 | C4: ← viene de Parámetros!B5 | E4: Producto | F4: OT | G4: Tarifa S/IVA (UF) | H4: Tarifa C/IVA (UF) | I4: Tarifa S/IVA ($) | J4: Tarifa C/IVA ($) | L4: Producto | M4: OT
A5: Mes actual (1° día) | B5: =[1]Parámetros!B9 -> 46174 | C5: ← viene de Parámetros!B9 | E5: AVANCE EXTERNO | F5: 1220005 | G5: =[1]Parámetros!B25 -> 0.32 | H5: =G5*1.19 -> 0.3808 | I5: =G5*$B$4 -> 12973.782 | J5: =H5*$B$4 -> 15438.801 | L5: PLAN ZERO PER | M5: 1320030
A6: Mes anterior (1° día) | B6: =[1]Parámetros!B10 -> 46143 | E6: SEG. DESGRAVAMEN | G6: =[1]Parámetros!B26 -> 0.26890756 | H6: =G6*1.19 -> 0.32 | I6: =G6*$B$4 -> 10902.338 | J6: =H6*$B$4 -> 12973.782 | L6: TC ADICIONAL | M6: 1220056
A7: Días hábiles mes actual | B7: =[1]Parámetros!B11 -> 21 | E7: PAGO FLEXIBLE | F7: 1220007 | G7: =[1]Parámetros!B27 -> 0.315 | H7: =G7*1.19 -> 0.37485 | I7: =G7*$B$4 -> 12771.067 | J7: =H7*$B$4 -> 15197.57 | L7: TC TITULAR | M7: 1220055
A8: Días hábiles mes anterior | B8: =[1]Parámetros!B12 -> 19 | E8: PLAN ZERO OPERA | G8: =[1]Parámetros!B28 -> 0.5 | H8: =G8*1.19 -> 0.595 | I8: =G8*$B$4 -> 20271.535 | J8: =H8*$B$4 -> 24123.127 | L8: PAGO FLEXIBLE | M8: 1220007
A9: Días trabajados mes actual | B9: =COUNTA(B23:B43) -> 1 | C9: ← automático (cuenta filas con fecha) | E9: PLAN ZERO PER | F9: 1320030 | G9: =[1]Parámetros!B29 -> 0.8 | H9: =G9*1.19 -> 0.952 | I9: =G9*$B$4 -> 32434.456 | J9: =H9*$B$4 -> 38597.003 | L9: AVANCE EXTERNO | M9: 1220005
A10: Pago Backoffice fijo | B10: =[1]Parámetros!B15 -> 8000000 | E10: PER | G10: =[1]Parámetros!B30 -> 0.25378151 | H10: =G10*1.19 -> 0.302 | I10: =G10*$B$4 -> 10289.082 | J10: =H10*$B$4 -> 12244.007
A11: Pago WEB extra | B11: =[1]Parámetros!B16 -> 10000000 | E11: TC TITULAR | F11: 1220055 | G11: =[1]Parámetros!B31 -> 0.6 | H11: =G11*1.19 -> 0.714 | I11: =G11*$B$4 -> 24325.842 | J11: =H11*$B$4 -> 28947.752
E12: TC ADICIONAL | F12: 1220056 | G12: =[1]Parámetros!B32 -> 0.7 | H12: =G12*1.19 -> 0.833 | I12: =G12*$B$4 -> 28380.149 | J12: =H12*$B$4 -> 33772.377
E13: TC DIGITAL | G13: =[1]Parámetros!B33 -> 0.7 | H13: =G13*1.19 -> 0.833 | I13: =G13*$B$4 -> 28380.149 | J13: =H13*$B$4 -> 33772.377
E14: TC TSYS | G14: =[1]Parámetros!B34 -> 0 | H14: =G14*1.19 -> 0 | I14: =G14*$B$4 -> 0 | J14: =H14*$B$4 -> 0
A17: BITÁCORA DIARIA - MES ACTUAL (JUNIO)
A19: AVANCE EXTERNO | E19: SEGUROS DESGRAVAMEN | H19: PAGO FLEXIBLE | J19: PLAN ZERO | N19: PER | O19: TARJETA DE CRÉDITO
A21: Día | B21: Fecha | C21: Nro. Op. | D21: Monto $ | E21: Nro. Op. | F21: Monto $ | G21: % Cruce | H21: Nro. Op. | I21: Monto $ | J21: Nro. Op. | K21: PER | L21: % Cruce PER | M21: Zero+TC | N21: Nro. Op. | O21: Titular | P21: Adicional | Q21: Digital | R21: TSYS
A23: =IF(B23="","",TEXT(B23,"dddd")) -> lunes | B23: 46174 | C23: 21 | D23: 103175000 | E23: 9 | F23: 73040 | G23: 0.42857143 | H23: 27 | I23: 113386875 | J23: 5 | K23: 2 | L23: 0 | M23: 0 | N23: 4 | O23: 28 | P23: 8 | Q23: 0 | R23: 0
A24: =IF(B24="","",TEXT(B24,"dddd"))
A25: =IF(B25="","",TEXT(B25,"dddd"))
A26: =IF(B26="","",TEXT(B26,"dddd"))
A27: =IF(B27="","",TEXT(B27,"dddd"))
A28: =IF(B28="","",TEXT(B28,"dddd"))
A29: =IF(B29="","",TEXT(B29,"dddd"))
A30: =IF(B30="","",TEXT(B30,"dddd"))
A31: =IF(B31="","",TEXT(B31,"dddd"))
A32: =IF(B32="","",TEXT(B32,"dddd"))
A33: =IF(B33="","",TEXT(B33,"dddd"))
A34: =IF(B34="","",TEXT(B34,"dddd"))
A35: =IF(B35="","",TEXT(B35,"dddd"))
... A43: =IF(B43="","",TEXT(B43,"dddd"))
B44: Acumulado | C44: =SUM(C23:C43) -> 21 | D44: =SUM(D23:D43) -> 103175000 | E44: =SUM(E23:E43) -> 9 | F44: =SUM(F23:F43) -> 73040 | G44: =IFERROR(AVERAGE(G23:G43),0) -> 0.42857143 | H44: =SUM(H23:H43) -> 27 | I44: =SUM(I23:I43) -> 113386875 | J44: =SUM(J23:J43) -> 5 | K44: =SUM(K23:K43) -> 2 | L44: =SUM(L23:L43) -> 0 | M44: =SUM(M23:M43) -> 0 | N44: =SUM(N23:N43) -> 4 | O44: =SUM(O23:O43) -> 28 | ... R44: =SUM(R23:R43) -> 0
A46: BITÁCORA DIARIA - MES ANTERIOR (MAYO)
A48: AVANCE EXTERNO | E48: SEGUROS DESGRAVAMEN | H48: PAGO FLEXIBLE | J48: PLAN ZERO | N48: PER | O48: TARJETA DE CRÉDITO
A50: Día | B50: Fecha | C50: Nro. Op. | D50: Monto $ | E50: Nro. Op. | F50: Monto $ | G50: % Cruce | H50: Nro. Op. | I50: Monto $ | J50: Nro. Op. | K50: PER | L50: % Cruce PER | M50: Zero+TC | N50: Nro. Op. | O50: Titular | P50: Adicional | Q50: Digital | R50: TSYS
A52: =IF(B52="","",TEXT(B52,"dddd")) -> lunes | B52: 46146 | C52: 5 | D52: 12300000 | E52: 1 | F52: 8037 | G52: 0.2 | H52: 29 | I52: 100824384 | J52: 6 | K52: 1 | L52: 0 | M52: 0 | N52: 19 | O52: 8 | P52: 6 | Q52: 0 | R52: 0
A53: =IF(B53="","",TEXT(B53,"dddd")) -> martes | B53: 46147 | C53: 18 | D53: 54535000 | E53: 1 | F53: 8040 | G53: 0.055555556 | H53: 90 | I53: 353989572 | J53: 11 | K53: 3 | L53: 0 | M53: 0 | N53: 16 | O53: 85 | P53: 42 | Q53: 2 | R53: 0
A54: =IF(B54="","",TEXT(B54,"dddd")) -> miércoles | B54: 46148 | C54: 29 | D54: 80897000 | E54: 11 | F54: 88446 | G54: 0.37931034 | H54: 98 | I54: 452034880 | J54: 6 | K54: 1 | L54: 0 | M54: 0 | N54: 7 | O54: 77 | P54: 68 | Q54: 1 | R54: 0
A55: =IF(B55="","",TEXT(B55,"dddd")) -> jueves | B55: 46149 | C55: 25 | D55: 90953782 | E55: 6 | F55: 48262 | G55: 0.24 | H55: 53 | I55: 166173662 | J55: 13 | K55: 4 | L55: 0 | M55: 0 | N55: 12 | O55: 49 | P55: 42 | Q55: 0 | R55: 0
A56: =IF(B56="","",TEXT(B56,"dddd")) -> viernes | B56: 46150 | C56: 16 | D56: 50309000 | E56: 6 | F56: 48270 | G56: 0.375 | H56: 94 | I56: 366459783 | J56: 11 | K56: 4 | L56: 0 | M56: 0 | N56: 10 | O56: 34 | P56: 41 | Q56: 1 | R56: 0
A57: =IF(B57="","",TEXT(B57,"dddd")) -> lunes | B57: 46153 | C57: 18 | D57: 70200000 | E57: 7 | F57: 56376 | G57: 0.38888889 | H57: 89 | I57: 230182745 | J57: 8 | K57: 0 | L57: 0 | M57: 0 | N57: 10 | O57: 34 | P57: 38 | Q57: 0 | R57: 0
...
